Workbook
Name Date: Dashboard!$S$3
Name Date_Range: OFFSET(Dashboard!$AF$4,0,0,MATCH(TODAY(),Dashboard!$AF$4:$AF$337,0)+1)
Name Flow_Range: OFFSET(Dashboard!$AG$4,0,0,MATCH(TODAY(),Dashboard!$AF$4:$AF$337,0)+1)

Sheet Accounts Tasks
A3: RC | C3: Accounts' Status
C4: Account | E4: Lead | G4: Status
C5: Globe | E5: Yaniv | G5: STOP (only up to 2 hrs work can be completed) Data Modelling required for Misaligned Component - MRF flow
C6: Sprint | E6: Yaniv | G6: STOP (only up to 2 hrs work can be completed)
C7: XLCom | E7: Maya | G7: STOP (only up to 2 hrs work can be completed) Wrong Charging, Quota Not Update - waiting for UTS-Krrish resolve, Unsync - needs remodeling per new format
C8: Cricket | E8: Yaniv | G8: STOP (only up to 2 hrs work can be completed)
C9: USCC | E9: Yaniv | G9: STOP (only up to 2 hrs work can be completed) Uploaded 2 dispatch flows
C10: TefArg | E10: Maya | G10: STOP (only up to 2 hrs work can be completed) Pending full classification by Rodrigo + Decision which flows to model - Ongoing
C11: Bell Canada | E11: Maya | G11: STOP (only up to 2 hrs work can be completed) "User ID / Password Issue" flow modelled - Waiting for Krrish and AO configurations on site
A12: 0.3 monthly | C12: Airtel | E12: Maya | G12: High priority Deployed "Order Not Generated", Attachment config. For "Order Not Generated", Parsing - new atom for "NMS Release Scenario"
C13: Metro PCS | E13: Maya | G13: STOP (only up to 2 hrs work can be completed)
A14: 0.25 one time | C14: TKS | E14: Maya | G14: To start
C16: Open Tasks - Non Dev | E16: FP | G16: Note
C17: Maya KT | E17: Yaniv, Maya | G17: Started going through the Amily web service code
C18: DevOps in Amily | E18: Yaniv | G18: On hold
C19: UTS querying service | E19: Yaniv | G19: A story was opened in Jira by Galit
C20: Cluster validation using partially labeld data applied on documents | E20: Yaniv, Maya
C21: Limitation to number of values parsed - Ask Bharati/Hetal

Sheet Dashboard
D2: =SUM(D5:D50) -> 38 | E2: =SUM(E5:E50) -> 1 | F2: =SUM(F5:F50) -> 2 | G2: =SUM(G5:G50) -> 14 | H2: =SUM(H5:H50) -> 6 | I2: =SUM(I5:I50) -> 6 | K2: =SUM(K5:K50) -> 8 | L2: =SUM(L5:L50) -> 0 | M2: =SUM(M5:M50) -> 0 | N2: =SUM(N5:N50) -> 0 | O2: =SUM(O5:O50) -> 6
D3: E2E Automation Flows | K3: Dispatch Flows | AF3: Date | AG3: Flows
C4: Account Status | D4: Prod. - Activated | E4: Prod. - Deactivated | F4: Labeling | G4: Dev. | H4: Dev. - Testing | I4: Descoped | K4: Prod. - Activated | L4: Prod. - Deactivated | M4: Dev. | N4: Dev. - Testing | O4: Descoped | AF4: 42948 | AG4: =COUNTIF(Workflows!$U$4:$U$4024,"<="&AF4) -> 0
C5: Globe | D5: =COUNTIFS(Workflows!$B$4:$B$519,$C5,Workflows!$D$4:$D$519,D$4) -> 7 | E5: =COUNTIFS(Workflows!$B$4:$B$519,$C5,Workflows!$D$4:$D$519,E$4) -> 0 | F5: =COUNTIFS(Workflows!$B$4:$B$519,$C5,Workflows!$D$4:$D$519,F$4) -> 0 | G5: =COUNTIFS(Workflows!$B$4:$B$519,$C5,Workflows!$D$4:$D$519,G$4) -> 1 | H5: =COUNTIFS(Workflows!$B$4:$B$519,$C5,Workflows!$D$4:$D$519,H$4) -> 1 | I5: =COUNTIFS(Workflows!$B$4:$B$519,$C5,Workflows!$D$4:$D$519,I$4) -> 0 | K5: =COUNTIFS('Dispatch flows'!$B$4:$B$74,$C5,'Dispatch flows'!$D$4:$D$74,K$4) -> 3 | L5: =COUNTIFS('Dispatch flows'!$B$4:$B$74,$C5,'Dispatch flows'!$D$4:$D$74,L$4) -> 0 | M5: =COUNTIFS('Dispatch flows'!$B$4:$B$74,$C5,'Dispatch flows'!$D$4:$D$74,M$4) -> 0 | N5: =COUNTIFS('Dispatch flows'!$B$4:$B$74,$C5,'Dispatch flows'!$D$4:$D$74,N$4) -> 0 | O5: =COUNTIFS('Dispatch flows'!$B$4:$B$74,$C5,'Dispatch flows'!$D$4:$D$74,O$4) -> 3 | AF5: 42949 | AG5: =COUNTIF(Workflows!$U$4:$U$4024,"<="&AF5) -> 0
C6: Sprint | D6: =COUNTIFS(Workflows!$B$4:$B$519,$C6,Workflows!$D$4:$D$519,D$4) -> 11 | E6: =COUNTIFS(Workflows!$B$4:$B$519,$C6,Workflows!$D$4:$D$519,E$4) -> 0 | F6: =COUNTIFS(Workflows!$B$4:$B$519,$C6,Workflows!$D$4:$D$519,F$4) -> 0 | G6: =COUNTIFS(Workflows!$B$4:$B$519,$C6,Workflows!$D$4:$D$519,G$4) -> 0 | H6: =COUNTIFS(Workflows!$B$4:$B$519,$C6,Workflows!$D$4:$D$519,H$4) -> 0 | I6: =COUNTIFS(Workflows!$B$4:$B$519,$C6,Workflows!$D$4:$D$519,I$4) -> 0 | K6: =COUNTIFS('Dispatch flows'!$B$4:$B$74,$C6,'Dispatch flows'!$D$4:$D$74,K$4) -> 3 | L6: =COUNTIFS('Dispatch flows'!$B$4:$B$74,$C6,'Dispatch flows'!$D$4:$D$74,L$4) -> 0 | M6: =COUNTIFS('Dispatch flows'!$B$4:$B$74,$C6,'Dispatch flows'!$D$4:$D$74,M$4) -> 0 | N6: =COUNTIFS('Dispatch flows'!$B$4:$B$74,$C6,'Dispatch flows'!$D$4:$D$74,N$4) -> 0 | O6: =COUNTIFS('Dispatch flows'!$B$4:$B$74,$C6,'Dispatch flows'!$D$4:$D$74,O$4) -> 0 | AF6: 42950 | AG6: =COUNTIF(Workflows!$U$4:$U$4024,"<="&AF6) -> 0
C7: XL Axiata | D7: =COUNTIFS(Workflows!$B$4:$B$519,$C7,Workflows!$D$4:$D$519,D$4) -> 4 | E7: =COUNTIFS(Workflows!$B$4:$B$519,$C7,Workflows!$D$4:$D$519,E$4) -> 1 | F7: =COUNTIFS(Workflows!$B$4:$B$519,$C7,Workflows!$D$4:$D$519,F$4) -> 1 | G7: =COUNTIFS(Workflows!$B$4:$B$519,$C7,Workflows!$D$4:$D$519,G$4) -> 0 | H7: =COUNTIFS(Workflows!$B$4:$B$519,$C7,Workflows!$D$4:$D$519,H$4) -> 1 | I7: =COUNTIFS(Workflows!$B$4:$B$519,$C7,Workflows!$D$4:$D$519,I$4) -> 0 | K7: =COUNTIFS('Dispatch flows'!$B$4:$B$74,$C7,'Dispatch flows'!$D$4:$D$74,K$4) -> 0 | L7: =COUNTIFS('Dispatch flows'!$B$4:$B$74,$C7,'Dispatch flows'!$D$4:$D$74,L$4) -> 0 | M7: =COUNTIFS('Dispatch flows'!$B$4:$B$74,$C7,'Dispatch flows'!$D$4:$D$74,M$4) -> 0 | N7: =COUNTIFS('Dispatch flows'!$B$4:$B$74,$C7,'Dispatch flows'!$D$4:$D$74,N$4) -> 0 | O7: =COUNTIFS('Dispatch flows'!$B$4:$B$74,$C7,'Dispatch flows'!$D$4:$D$74,O$4) -> 0 | AF7: 42951 | AG7: =COUNTIF(Workflows!$U$4:$U$4024,"<="&AF7) -> 0
C8: Cricket | D8: =COUNTIFS(Workflows!$B$4:$B$519,$C8,Workflows!$D$4:$D$519,D$4) -> 7 | E8: =COUNTIFS(Workflows!$B$4:$B$519,$C8,Workflows!$D$4:$D$519,E$4) -> 0 | F8: =COUNTIFS(Workflows!$B$4:$B$519,$C8,Workflows!$D$4:$D$519,F$4) -> 0 | G8: =COUNTIFS(Workflows!$B$4:$B$519,$C8,Workflows!$D$4:$D$519,G$4) -> 0 | H8: =COUNTIFS(Workflows!$B$4:$B$519,$C8,Workflows!$D$4:$D$519,H$4) -> 1 | I8: =COUNTIFS(Workflows!$B$4:$B$519,$C8,Workflows!$D$4:$D$519,I$4) -> 6 | K8: =COUNTIFS('Dispatch flows'!$B$4:$B$74,$C8,'Dispatch flows'!$D$4:$D$74,K$4) -> 0 | L8: =COUNTIFS('Dispatch flows'!$B$4:$B$74,$C8,'Dispatch flows'!$D$4:$D$74,L$4) -> 0 | M8: =COUNTIFS('Dispatch flows'!$B$4:$B$74,$C8,'Dispatch flows'!$D$4:$D$74,M$4) -> 0 | N8: =COUNTIFS('Dispatch flows'!$B$4:$B$74,$C8,'Dispatch flows'!$D$4:$D$74,N$4) -> 0 | O8: =COUNTIFS('Dispatch flows'!$B$4:$B$74,$C8,'Dispatch flows'!$D$4:$D$74,O$4) -> 0 | AF8: 42952 | AG8: =COUNTIF(Workflows!$U$4:$U$4024,"<="&AF8) -> 0
C9: USCC | D9: =COUNTIFS(Workflows!$B$4:$B$519,$C9,Workflows!$D$4:$D$519,D$4) -> 4 | E9: =COUNTIFS(Workflows!$B$4:$B$519,$C9,Workflows!$D$4:$D$519,E$4) -> 0 | F9: =COUNTIFS(Workflows!$B$4:$B$519,$C9,Workflows!$D$4:$D$519,F$4) -> 0 | G9: =COUNTIFS(Workflows!$B$4:$B$519,$C9,Workflows!$D$4:$D$519,G$4) -> 2 | H9: =COUNTIFS(Workflows!$B$4:$B$519,$C9,Workflows!$D$4:$D$519,H$4) -> 2 | I9: =COUNTIFS(Workflows!$B$4:$B$519,$C9,Workflows!$D$4:$D$519,I$4) -> 0 | K9: =COUNTIFS('Dispatch flows'!$B$4:$B$74,$C9,'Dispatch flows'!$D$4:$D$74,K$4) -> 2 | L9: =COUNTIFS('Dispatch flows'!$B$4:$B$74,$C9,'Dispatch flows'!$D$4:$D$74,L$4) -> 0 | M9: =COUNTIFS('Dispatch flows'!$B$4:$B$74,$C9,'Dispatch flows'!$D$4:$D$74,M$4) -> 0 | N9: =COUNTIFS('Dispatch flows'!$B$4:$B$74,$C9,'Dispatch flows'!$D$4:$D$74,N$4) -> 0 | O9: =COUNTIFS('Dispatch flows'!$B$4:$B$74,$C9,'Dispatch flows'!$D$4:$D$74,O$4) -> 3 | AF9: 42953 | AG9: =COUNTIF(Workflows!$U$4:$U$4024,"<="&AF9) -> 8
C10: Bell Canada | D10: =COUNTIFS(Workflows!$B$4:$B$519,$C10,Workflows!$D$4:$D$519,D$4) -> 0 | E10: =COUNTIFS(Workflows!$B$4:$B$519,$C10,Workflows!$D$4:$D$519,E$4) -> 0 | F10: =COUNTIFS(Workflows!$B$4:$B$519,$C10,Workflows!$D$4:$D$519,F$4) -> 0 | G10: =COUNTIFS(Workflows!$B$4:$B$519,$C10,Workflows!$D$4:$D$519,G$4) -> 3 | H10: =COUNTIFS(Workflows!$B$4:$B$519,$C10,Workflows!$D$4:$D$519,H$4) -> 0 | I10: =COUNTIFS(Workflows!$B$4:$B$519,$C10,Workflows!$D$4:$D$519,I$4) -> 0 | K10: =COUNTIFS('Dispatch flows'!$B$4:$B$74,$C10,'Dispatch flows'!$D$4:$D$74,K$4) -> 0 | L10: =COUNTIFS('Dispatch flows'!$B$4:$B$74,$C10,'Dispatch flows'!$D$4:$D$74,L$4) -> 0 | M10: =COUNTIFS('Dispatch flows'!$B$4:$B$74,$C10,'Dispatch flows'!$D$4:$D$74,M$4) -> 0 | N10: =COUNTIFS('Dispatch flows'!$B$4:$B$74,$C10,'Dispatch flows'!$D$4:$D$74,N$4) -> 0 | O10: =COUNTIFS('Dispatch flows'!$B$4:$B$74,$C10,'Dispatch flows'!$D$4:$D$74,O$4) -> 0 | AF10: 42954 | AG10: =COUNTIF(Workflows!$U$4:$U$4024,"<="&AF10) -> 8
C11: Airtel | D11: =COUNTIFS(Workflows!$B$4:$B$519,$C11,Workflows!$D$4:$D$519,D$4) -> 5 | E11: =COUNTIFS(Workflows!$B$4:$B$519,$C11,Workflows!$D$4:$D$519,E$4) -> 0 | F11: =COUNTIFS(Workflows!$B$4:$B$519,$C11,Workflows!$D$4:$D$519,F$4) -> 0 | G11: =COUNTIFS(Workflows!$B$4:$B$519,$C11,Workflows!$D$4:$D$519,G$4) -> 3 | H11: =COUNTIFS(Workflows!$B$4:$B$519,$C11,Workflows!$D$4:$D$519,H$4) -> 1 | I11: =COUNTIFS(Workflows!$B$4:$B$519,$C11,Workflows!$D$4:$D$519,I$4) -> 0 | K11: =COUNTIFS('Dispatch flows'!$B$4:$B$74,$C11,'Dispatch flows'!$D$4:$D$74,K$4) -> 0 | L11: =COUNTIFS('Dispatch flows'!$B$4:$B$74,$C11,'Dispatch flows'!$D$4:$D$74,L$4) -> 0 | M11: =COUNTIFS('Dispatch flows'!$B$4:$B$74,$C11,'Dispatch flows'!$D$4:$D$74,M$4) -> 0 | N11: =COUNTIFS('Dispatch flows'!$B$4:$B$74,$C11,'Dispatch flows'!$D$4:$D$74,N$4) -> 0 | O11: =COUNTIFS('Dispatch flows'!$B$4:$B$74,$C11,'Dispatch flows'!$D$4:$D$74,O$4) -> 0 | AF11: 42955 | AG11: =COUNTIF(Workflows!$U$4:$U$4024,"<="&AF11) -> 8
C12: Tef Argentina | D12: =COUNTIFS(Workflows!$B$4:$B$519,$C12,Workflows!$D$4:$D$519,D$4) -> 0 | E12: =COUNTIFS(Workflows!$B$4:$B$519,$C12,Workflows!$D$4:$D$519,E$4) -> 0 | F12: =COUNTIFS(Workflows!$B$4:$B$519,$C12,Workflows!$D$4:$D$519,F$4) -> 0 | G12: =COUNTIFS(Workflows!$B$4:$B$519,$C12,Workflows!$D$4:$D$519,G$4) -> 1 | H12: =COUNTIFS(Workflows!$B$4:$B$519,$C12,Workflows!$D$4:$D$519,H$4) -> 0 | I12: =COUNTIFS(Workflows!$B$4:$B$519,$C12,Workflows!$D$4:$D$519,I$4) -> 0 | K12: =COUNTIFS('Dispatch flows'!$B$4:$B$74,$C12,'Dispatch flows'!$D$4:$D$74,K$4) -> 0 | L12: =COUNTIFS('Dispatch flows'!$B$4:$B$74,$C12,'Dispatch flows'!$D$4:$D$74,L$4) -> 0 | M12: =COUNTIFS('Dispatch flows'!$B$4:$B$74,$C12,'Dispatch flows'!$D$4:$D$74,M$4) -> 0 | N12: =COUNTIFS('Dispatch flows'!$B$4:$B$74,$C12,'Dispatch flows'!$D$4:$D$74,N$4) -> 0 | O12: =COUNTIFS('Dispatch flows'!$B$4:$B$74,$C12,'Dispatch flows'!$D$4:$D$74,O$4) -> 0 | AF12: 42956 | AG12: =COUNTIF(Workflows!$U$4:$U$4024,"<="&AF12) -> 8
C13: MetroPCS | D13: =COUNTIFS(Workflows!$B$4:$B$519,$C13,Workflows!$D$4:$D$519,D$4) -> 0 | E13: =COUNTIFS(Workflows!$B$4:$B$519,$C13,Workflows!$D$4:$D$519,E$4) -> 0 | F13: =COUNTIFS(Workflows!$B$4:$B$519,$C13,Workflows!$D$4:$D$519,F$4) -> 1 | G13: =COUNTIFS(Workflows!$B$4:$B$519,$C13,Workflows!$D$4:$D$519,G$4) -> 0 | H13: =COUNTIFS(Workflows!$B$4:$B$519,$C13,Workflows!$D$4:$D$519,H$4) -> 0 | I13: =COUNTIFS(Workflows!$B$4:$B$519,$C13,Workflows!$D$4:$D$519,I$4) -> 0 | K13: =COUNTIFS('Dispatch flows'!$B$4:$B$74,$C13,'Dispatch flows'!$D$4:$D$74,K$4) -> 0 | L13: =COUNTIFS('Dispatch flows'!$B$4:$B$74,$C13,'Dispatch flows'!$D$4:$D$74,L$4) -> 0 | M13: =COUNTIFS('Dispatch flows'!$B$4:$B$74,$C13,'Dispatch flows'!$D$4:$D$74,M$4) -> 0 | N13: =COUNTIFS('Dispatch flows'!$B$4:$B$74,$C13,'Dispatch flows'!$D$4:$D$74,N$4) -> 0 | O13: =COUNTIFS('Dispatch flows'!$B$4:$B$74,$C13,'Dispatch flows'!$D$4:$D$74,O$4) -> 0 | AF13: 42957 | AG13: =COUNTIF(Workflows!$U$4:$U$4024,"<="&AF13) -> 8
C14: Telkomsel | D14: =COUNTIFS(Workflows!$B$4:$B$519,$C14,Workflows!$D$4:$D$519,D$4) -> 0 | E14: =COUNTIFS(Workflows!$B$4:$B$519,$C14,Workflows!$D$4:$D$519,E$4) -> 0 | F14: =COUNTIFS(Workflows!$B$4:$B$519,$C14,Workflows!$D$4:$D$519,F$4) -> 0 | G14: =COUNTIFS(Workflows!$B$4:$B$519,$C14,Workflows!$D$4:$D$519,G$4) -> 4 | H14: =COUNTIFS(Workflows!$B$4:$B$519,$C14,Workflows!$D$4:$D$519,H$4) -> 0 | I14: =COUNTIFS(Workflows!$B$4:$B$519,$C14,Workflows!$D$4:$D$519,I$4) -> 0 | K14: =COUNTIFS('Dispatch flows'!$B$4:$B$74,$C14,'Dispatch flows'!$D$4:$D$74,K$4) -> 0 | L14: =COUNTIFS('Dispatch flows'!$B$4:$B$74,$C14,'Dispatch flows'!$D$4:$D$74,L$4) -> 0 | M14: =COUNTIFS('Dispatch flows'!$B$4:$B$74,$C14,'Dispatch flows'!$D$4:$D$74,M$4) -> 0 | N14: =COUNTIFS('Dispatch flows'!$B$4:$B$74,$C14,'Dispatch flows'!$D$4:$D$74,N$4) -> 0 | O14: =COUNTIFS('Dispatch flows'!$B$4:$B$74,$C14,'Dispatch flows'!$D$4:$D$74,O$4) -> 0 | AF14: 42958 | AG14: =COUNTIF(Workflows!$U$4:$U$4024,"<="&AF14) -> 8
AF15: 42959 | AG15: =COUNTIF(Workflows!$U$4:$U$4024,"<="&AF15) -> 8
AF16: 42960 | AG16: =COUNTIF(Workflows!$U$4:$U$4024,"<="&AF16) -> 8
AF17: 42961 | AG17: =COUNTIF(Workflows!$U$4:$U$4024,"<="&AF17) -> 8
AF18: 42962 | AG18: =COUNTIF(Workflows!$U$4:$U$4024,"<="&AF18) -> 8
AF19: 42963 | AG19: =COUNTIF(Workflows!$U$4:$U$4024,"<="&AF19) -> 8
AF20: 42964 | AG20: =COUNTIF(Workflows!$U$4:$U$4024,"<="&AF20) -> 8
AF21: 42965 | AG21: =COUNTIF(Workflows!$U$4:$U$4024,"<="&AF21) -> 8
AF22: 42966 | AG22: =COUNTIF(Workflows!$U$4:$U$4024,"<="&AF22) -> 8
AF23: 42967 | AG23: =COUNTIF(Workflows!$U$4:$U$4024,"<="&AF23) -> 8
AF24: 42968 | AG24: =COUNTIF(Workflows!$U$4:$U$4024,"<="&AF24) -> 8
AF25: 42969 | AG25: =COUNTIF(Workflows!$U$4:$U$4024,"<="&AF25) -> 8
AF26: 42970 | AG26: =COUNTIF(Workflows!$U$4:$U$4024,"<="&AF26) -> 8
... AF337: 43281 | AG337: =COUNTIF(Workflows!$U$4:$U$4024,"<="&AF337) -> 37

Sheet Workflows
B1: Link
B2: Account | D2: Flow | H2: Krrish Dev. | J2: Classification | L2: Threshold Config | N2: Parsing | W2: % in Training data | AA2: Recall on test set | AD2: Full Auto Error on test set
D3: Phase | E3: Name | F3: Krrish Name | G3: Type | J3: Status | K3: Model | N3: Entity | O3: Atom | P3: Configuration | Q3: Note | R3: Status | T3: Description | U3: Production Date | W3: Total | X3: External | Y3: Internal | AA3: TH = 0.5 | AB3: Lower TH | AD3: TH = 0.5 | AE3: Higher TH | AF3: MRFPR
B4: Globe | D4: Prod. - Activated | E4: Rated events extraction | F4: Rated Events Extraction | G4: Ext. | J4: Trained Desc - 0.5, Summ - 0.5 | K4: 1. N gram - 2 2. Chi2 - 20% 3. Random Forest - 100 trees | L4: 0.5, 0.3 | N4: MSISDN (M) | O4: Phone Number | P4: PhoneNumberExtractor(exclusion_list = ["requestor phone", "contact phone", "requestor contact","requestor's phone", "contact's phone", "requestor's contact"], first_digit = 9) | R4: configured | T4: User/s usage report (data/voice/SMS) | U4: 42953 | W4: 0.0491 | X4: 0.0516 | Y4: - | AA4: 0.85 | AB4: =161/189 -> 0.85185185 | AD4: 0.11 | AE4: 0.11 | AF4: 1-8 | AG4: =1/8 -> 0.125
N5: DATE_FROM, DATE_TO | O5: Date-Range | P5: DateRangeExtractor(from_range_name = 'DATE_FROM', to_range_name = 'DATE_TO', time_zone = 'Asia/Manila') | R5: configured
N6: VOICE | O6: Regex | P6: RegexExtractor(extraction_regex = r"""voice|call?s""" , indicator = True) | R6: configured
N7: SMS | O7: Regex | P7: RegexExtractor(extraction_regex = r"""sms|text|txt|msg|messag?e?s""" , indicator = True) | R7: configured
N8: DATA | O8: Regex | P8: RegexExtractor(extraction_regex = r"""data|internet""" , indicator = True) | R8: configured
N9: ROAMING_IND | O9: Regex | P9: RegexExtractor(extraction_regex = r"""\\sroaming|\\sroam\\s""" , indicator = True) | R9: configured
B10: Globe | D10: Prod. - Activated | E10: LTP no load received | F10: LTP_NO_LOAD_RECEIVE | G10: Ext. | L10: 0.7,0.15 | N10: MSISDN (M) | O10: Phone Number | P10: PhoneNumberExtractor(exclusion_list = ["requestor phone", "contact phone", "requestor contact"] ,first_digit = 9) | R10: configured | T10: LTP stands for Load Tipid Plan. A Hybrid prepaid-postpaid program. Training issue. RPL flow where subscriber did not received monthly recharge. This is a training issue due to CSR did not validate completely why subs did not receive load and upon checking. It is a valid scenario where subs is still in collection. | U10: 42953 | W10: 0.0259 | X10: 0.0272 | Y10: - | AA10: 0.88 | AB10: 0.88 | AD10: 0.05 | AE10: 0.05 | AF10: 1-9 | AG10: =1/9 -> 0.11111111
N11: SEEDING_DATE | O11: Regex | P11: RegexExtractor(extraction_regex = r"""((seed|sedd|seeed)(.{1,50})(\\b((?:[1-9]|0[1-9]|[1-2][0-9]|3[0-1]))(\\s|$)))|((\\b1st)|(21st)|(31st)|(\\b2nd)|(22nd)|(10th)|(11th)|(12th)|(13th)|(\\b3rd)|(23rd)|([1-2]?(0|[4-9])th))""" , integer_indicator = True, length_limit = 2, default_value = datetime.datetime.now().strftime('%d')) | R11: configured
B12: Globe | D12: Prod. - Activated | E12: ASMM variance found base | F12: MEDIATION_REPORT | G12: Ext. | L12: 0.5,0.5 | N12: FILE_IDENTIFIER (M) | O12: Globe_ASMM | P12: Globe_ASMMVariance_FileIdExtractor() | Q12: Comes in an attached .zip file | R12: configured | T12: ASMM Variance found base. Summary contains "Variance found base on ASMM VS TC base on daily analysis and A&C balance report“ | U12: 42953 | W12: 0.0092 | X12: 0.0097 | Y12: - | AA12: 1 | AB12: 1 | AD12: 0 | AE12: 0 | AF12: 0-0 | AG12: 0
B13: Globe | D13: Prod. - Activated | E13: Hold activity cancellation | F13: Hold Activity Cancellation | G13: Ext. | L13: 0.4,0.2 | N13: ORDER_ID | O13: Regex | P13: RegexExtractor(extraction_regex = r"""(\\D\\d{9}\\d?)([a]|[A])""", integer_indicator = True) | R13: configured | T13: Order cancellation in Hold activity. Script is being used to enable cancel order button | U13: 42953 | W13: 0.0076 | X13: 0.008 | Y13: - | AA13: 0.4 | AB13: 0.84705882 | AD13: 0.03 | AE13: 0.03 | AF13: 5-32 | AG13: =5/32 -> 0.15625
N14: MSISDN | O14: Phone Number | P14: PhoneNumberExtractor(exclusion_list = ["requestor phone", "contact phone", "requestor contact","requestor's phone", "contact's phone", "requestor's contact"], first_digit = 9) | R14: configured
B15: Globe | D15: Prod. - Activated | E15: Duo Alignment | F15: Duo Alignment | G15: Ext. | L15: 0.5,0.25 | N15: Multiple | O15: Globe_Duoalignment | P15: Default Values | R15: configured | U15: 43089 | W15: 0.0165 | X15: 0.0173 | Y15: - | AF15: 0-1 | AG15: 0
B16: Globe | D16: Prod. - Activated | E16: Reconnection Checking | F16: Reconnection | G16: Ext. | L16: 0.7, 0.25 | N16: MSISDN | O16: Phone Number | P16: PhoneNumberExtractor(exclusion_list = ["requestor phone", "contact phone", "requestor contact","requestor's phone", "contact's phone", "requestor's contact"], first_digit = 9) | R16: configured | U16: 42988 | W16: 0.0132 | X16: 0.0138 | Y16: - | AF16: 11-25 | AG16: =11/25 -> 0.44
N17: TICKET_DATE | O17: Create Date | P17: CreateDateExtractor(timezone_offset = 13)
B18: Globe | D18: Prod. - Activated | E18: Bulk Barring | F18: Bulk Barring | G18: Ext. | L18: 0.5,0.4 | N18: DATA, File | O18: Globe_Bulkbarring | P18: GlobeBulkbarringExtractor() | Q18: May come in an attached .zip file | R18: configured | U18: 43089
B19: Globe | D19: Dev. | E19: Misaligned Component - MRF | G19: Ext. | N19: MSISDN
N20: Cycle_Month | Q20: if date range - last date
N21: Cycle_Year | Q21: usually prefaced by "Occurrence Date"
B22: Globe | D22: Dev. - Testing | E22: SRM Extraction | F22: SRM Extraction | G22: Ext. | L22: 0.5,0.3 | N22: Multiple | O22: GlobeSrmExtractionExtractor | P22: GlobeSrmExtractionExtractor() | R22: configured
N23: Request_Type | O23: Regex | P23: RegexExtractor("entity_name"= "Request_Type", "extraction_regex"= "(?<=Request\\sType(?!\\n)).*", "remove_char"=":", "replace_char"= ["^\\s",""]) | R23: configured
N24: Resource_Type | O24: Regex | P24: RegexExtractor("entity_name"= "Resource_Type", "extraction_regex"= "(?<=Resource\\sType(?!\\n)).*", "remove_char"=":", "replace_char"= ["^\\s",""]) | R24: configured
N25: Resource | O25: Regex | P25: RegexExtractor("entity_name"= "Resource", "extraction_regex"= "(?<=Resource)(:?)(\\s?)\\d.*", "remove_char"=":", "replace_char"= ["^\\s",""]) | R25: configured
N26: Status | O26: Regex | P26: RegexExtractor("entity_name"= "Status", "extraction_regex"= "(?<=Status(?!\\n)).*", "remove_char"=":", "replace_char"= ["^\\s",""]) | R26: configured
N27: Category | O27: Regex | P27: RegexExtractor("entity_name"= "Category", "extraction_regex"= "(?<=Category(?!\\n)).*", "remove_char"=":", "replace_char"= ["^\\s",""]) | R27: configured
N28: Area_Name | O28: Regex | P28: RegexExtractor("entity_name"= "Area_Name", "extraction_regex"= "(?<=Area\\sName(?!\\n)).*", "remove_char"=":", "replace_char"= ["^\\s",""]) | R28: configured
N29: Post_Pre | O29: Regex | P29: RegexExtractor("entity_name"= "Post_Pre", "extraction_regex"= "(?<=Post\\s\/\\sPre(?!\\n)).*", "remove_char"=":", "replace_char"= ["^\\s",""]) | R29: configured
N30: Date_From | O30: Regex | P30: RegexExtractor("entity_name"= "Date_From", "extraction_regex"= "(?<=Date\\sFrom(?!\\n)).*", "remove_char"=":", "replace_char"= ["^\\s",""]) | R30: configured
N31: Date_To | O31: Regex | P31: RegexExtractor("entity_name"= "Date_To", "extraction_regex"= "(?<=Date\\sTo(?!\\n)).*", "remove_char"=":", "replace_char"= ["^\\s",""]) | R31: configured
B33: Sprint | D33: Prod. - Activated | E33: Complete order | F33: complete order | G33: Ext. | J33: Trained Desc - 0.5, Summ - 0.5 | K33: 1. N gram - 2 2. Chi2 - 20% 3. Random Forest - 100 trees | L33: 0.8,0.5 | N33: Order_Number (M) | O33: Regex | P33: RegexExtractor(extraction_regex =r"""((COM\\d)|(DM\\d{2}))-?O-?\\d{6}\\d?\\d?""", remove_char = "-", upper_case = True) | R33: configured | T33: Completing orders that have gotten stuck in an incomplete status | U33: 42953 | W33: 0.0203 | X33: 0.0407 | Y33: - | AA33: 0.92 | AB33: 0.92 | AD33: 0.09 | AE33: 0.04 | AF33: 10-37 | AG33: =10/37 -> 0.27027027
B34: Sprint | D34: Prod. - Activated | E34: MPD date incorrect | F34: Sprint_INCORRECT MPD DATE CORRECTED | G34: Ext. | L34: 0.7,0.5 | N34: BAN (M) | O34: Regex | P34: RegexExtractor(extraction_regex =r"""(^|\\D)\d{9}(\\b|\\D)""",exclusion_list = ["Secondary", "secondary"],exclusion_offset=30, unique_indicator = False, integer_indicator = True) | Q34: May appear in the Summary field, Take only Primary number | R34: configured | T34: Resetting monthly payment dates on suspended prepaid accounts | U34: 42953 | W34: 0.0037 | X34: 0.0074 | Y34: - | AA34: 0.67 | AB34: 0.67 | AD34: 0.12 | AE34: 0.02 | AF34: 6-17 | AG34: =6/17 -> 0.35294118
B35: Sprint | D35: Prod. - Activated | E35: Re-push Order | F35: Repush Order Line | G35: Ext. | L35: 0.5 0.5 | N35: Order_Number (M) | O35: Sprint_Repush | R35: configured | U35: 42988 | W35: 0.0086 | X35: 0.0173 | Y35: - | AA35: 1 | AB35: 1 | AD35: 0 | AE35: 0 | AF35: 0-0 | AG35: 0
B36: Sprint | D36: Prod. - Activated | E36: Edit Memo | F36: Sprint_Mask Memo | G36: Ext. | L36: 0.6,0.2 | N36: BAN | O36: Regex | P36: RegexExtractor(extraction_regex =r"""(^|\\D)\d{9}(\\b|\\D)""", inclusion_list=["BAN","BAN:"], inclusion_offset = 20, unique_indicator = False, integer_indicator = True) | R36: configured | U36: 42988 | W36: 0.0115 | X36: 0.0231 | Y36: - | AA36: 0.92 | AB36: 1 | AD36: 0.06 | AE36: 0.04 | AF36: 2-11 | AG36: =2/11 -> 0.18181818
N37: PTN | O37: Phone Number | P37: PhoneNumberExtractor(exclusion_list = ["requestor phone", "contact phone", "requestor contact","Office Phone","Mobile Phone","Number"]) | R37: configured
N38: Memo_ID | O38: Regex | P38: RegexExtractor(extraction_regex =r"""(^|\\D)I?\\d?\\d{10}(\\b|\\D)""",inclusion_list = ["Memo ID"], inclusion_offset = 20, remove_char = " ", upper_case = True) | R38: configured
N39: Memo_Details_to_Remove | O39: Regex | P39: RegexExtractor(extraction_regex =r"""Memo\\s{,3}Details\\s{,3}to\\s{,3}Remove:(.+)\\n""",remove_char = "(m|M)emo\\s{,3}(d|D)etails\\s{,3}(T|t)o\\s{,3}(r|R)emove:") | R39: configured
B40: Sprint | D40: Prod. - Activated | E40: Clear PI PTN | F40: Sprint Clear PI PTN | G40: Ext. | L40: 0.4,0.1 | N40: PTN | O40: Phone Number | P40: PhoneNumberExtractor(exclusion_list = ["requestor phone", "contact phone", "requestor contact","Office Phone","Mobile Phone","Number"]) | R40: configured | U40: 43067
B41: Sprint | D41: Prod. - Activated | E41: Cancel Order | F41: Sprint Cancel Order | G41: Ext. | L41: 0.6, 0.3 | N41: Order_Number (M) | O41: Regex | P41: RegexExtractor(extraction_regex =r"""((COM\\d)|(DM\\d{2}))-?O-?\\d{6}\\d?\\d?""", remove_char = "-", upper_case = True) | R41: configured | U41: 43053
...

Sheet Dispatch flows
B2: Account | D2: Flow | H2: Krrish Dev. | J2: Classification | L2: Threshold Config | R2: % in Training data | V2: Recall on test set | Y2: Full Auto Error on test set
D3: Phase | E3: Support Group | F3: Support Group ID | G3: Flow Name | J3: Status | K3: Model | O3: Description | P3: Production Date | R3: Total | S3: External | T3: Internal | V3: TH = 0.5 | W3: Lower TH | Y3: TH = 0.5 | Z3: Higher TH
B4: Globe | D4: Prod. - Activated | E4: NBU | F4: SGP000000001133 | G4: Business | J4: Trained Desc - 0.5, Summ - 0.5 | K4: 1. N gram - 2 2. Chi2 - 20% 3. Random Forest - 200 trees | L4: 0.5 | P4: 42988
B5: Globe | D5: Prod. - Activated | E5: EPC | F5: SGP000000001130 | G5: Service Configuration | L5: 0.3 | P5: 42988
B6: Globe | D6: Descoped | E6: Usage | F6: SGP000000001367 | G6: PER Downstream Variance | L6: 0.3 | P6: 42988
B7: Globe | D7: Descoped | G7: Trending files with zero records | L7: 0.3
B8: Globe | D8: Descoped | G8: Variance found on CDR | L8: 0.3
B9: Globe | D9: Prod. - Activated | G9: Rejects | L9: 0.3 | P9: 43084
B11: USCC | D11: Descoped | G11: Amdocs SEVA | J11: Trained Desc - 0.5, Summ - 0.5 | K11: 1. N gram - 2 2. Chi2 - 20% 3. Random Forest - 200 trees | L11: 0.5
B12: USCC | D12: Prod. - Activated | G12: Recycle Event issue | L12: 0.6 | P12: 43116
B13: USCC | D13: Descoped | G13: Accelerate Device Financing | L13: 0.3
B14: USCC | D14: Descoped | G14: EOM | L14: 0.5
B15: USCC | D15: Prod. - Activated | G15: AR1JRNLEXT Running Long | L15: 0.4 | P15: 43116
B17: Sprint | D17: Prod. - Activated | G17: Sprint_API | J17: Trained Desc - 0.5, Summ - 0.5 | K17: 1. N gram - 2 2. Chi2 - 20% 3. Random Forest - 200 trees | L17: 0.5 | P17: 43167
B18: Sprint | D18: Prod. - Activated | G18: Sprint_DRF | L18: 0.5 | P18: 43167
B19: Sprint | D19: Prod. - Activated | G19: Sprint_MonAdjust | L19: 0.5 | P19: 43167

Sheet Amily PoC Status
B2: Globe | L2: Clustering
B4: Flow | D4: Classification | H4: Parsing | L4: Account | M4: Internal/External | N4: Supervised Evaluation | O4: Status
D5: IBM | E5: SAS | F5: FOSS | H5: IBM | I5: SAS | J5: FOSS | L5: Globe | M5: External | N5: Yes
B6: ASMM Variance found base | L6: Sprint | M6: Internal | N6: No
B7: Hold Activity Cancellation | I7: Evaluate | J7: Code | L7: TKS | M7: External | N7: No
B8: LTP No Load Receive | F8: ` | L8: TKS | M8: External | N8: Yes - Globe
B9: Misaligned Component - MRF | L9: TKS | M9: External | N9: Yes - Sprint
B10: PER Downstream Variance | L10: Metro | M10: External | N10: Yes - Globe
B11: Rated Events Extraction | I11: Evaluate | L11: Metro | M11: External | N11: Yes - Sprint
B12: Service Configuration | L12: XL Axiata | M12: External | N12: No
B13: Trending files with zero records
B14: Variance found on CDR
B15: Other | L15: Deployment feasibility PoC - all 3 tools
L16: Robust deployment feasibility PoC - with or w/o source code on
L17: OCR in python
B18: Sprint | L18: Gitlab
B20: Flow | D20: Classification | H20: Parsing
D21: IBM | E21: SAS | F21: FOSS | H21: IBM | I21: SAS | J21: FOSS
B22: Cancel Subscriber
B23: Complete Order | I23: Evaluate
B24: Daily DRF | I24: Evaluate | J24: Code
B25: Funds Not Sweeping
B26: MPD date incorrect
B27: Update PTN | I27: Evaluate | J27: Code
B28: Other

Sheet Amily PoC Contacts
C2: Vendor | E2: Name | G2: Phone Number | I2: E-mail
C3: IBM | E3: Jorge Vulej | G3: 050-9926431 | I3: ITZHAKVULEJ@IBM.COM
C4: IBM | E4: Omer Mizrachi | G4: 058-6485787 | I4: OMERMI@il.ibm.com
C5: SAS | E5: Yoni Barak | G5: 054-6400073 | I5: Jonathanb@miac.com
C6: SAS | E6: Hagay Goldman | G6: 052-6678805 | I6: Hagay.Goldman@sas.com
C7: SAS | E7: Dina Gelfond | G7: 052-8195582 | I7: DinaG@miac.com
C8: FOSS | E8: Yuval Feinstein | G8: 058-5113545 | I8: fyuval@gmail.com
